<?xml version="1.0" ?>
<!-- =================================================================================== -->
<!-- |    This document was autogenerated by xacro from /home/tec_di/ros_ws/src/cyton_gamma_1500_description/cyton_gamma_1500.urdf.xacro | -->
<!-- |    EDITING THIS FILE BY HAND IS NOT RECOMMENDED                                 | -->
<!-- =================================================================================== -->
<robot name="cyton_gamma_1500" xmlns:xacro="http://www.ros.org/wiki/xacro">
  <gazebo>
    <plugin filename="libgazebo_ros_joint_state_publisher.so" name="joint_state_publisher">
      <jointName>joint0, joint1, joint2, joint3, joint4, joint5, joint6, gripper_joint, gripper_joint2</jointName>
    </plugin>
  </gazebo>
  <link name="base_footprint">
    <visual>
      <origin rpy="0 0 0" xyz="0 0 0"/>
      <geometry>
        <sphere radius="0.001"/>
      </geometry>
      <material name="white">
        <color rgba="1 1 1 1"/>
      </material>
    </visual>
  </link>
  <joint name="base_joint" type="fixed">
    <parent link="base_footprint"/>
    <child link="base_link"/>
    <origin rpy="0 0 0" xyz="0.0 0.0 0.0"/>
  </joint>
  <link name="base_link">
    <visual>
      <origin rpy="0 0 0" xyz="0 0 0"/>
      <geometry>
        <mesh filename="package://cyton_gamma_1500_description/meshes/base.dae"/>
      </geometry>
    </visual>
    <collision>
      <origin xyz="0 0.0115 0.047"/>
      <geometry>
        <box size="0.154 0.177 0.094"/>
      </geometry>
    </collision>
    <inertial>
      <mass value="100.0"/>
      <origin rpy="0 0 0" xyz="0 0 0"/>
      <inertia ixx="1.1027" ixy="0" ixz="0" iyy="1.1027" iyz="0" izz="1.1027"/>
    </inertial>
  </link>
  <joint name="joint0" type="revolute">
    <parent link="base_link"/>
    <child link="shoulder_roll"/>
    <origin rpy="0 0 0" xyz="0 0 0.05315"/>
    <limit effort="100.0" lower="-2.618" upper="2.618" velocity="1.0"/>
    <axis xyz="0 0 1"/>
  </joint>
  <link name="shoulder_roll">
    <visual>
      <origin rpy="1.5708 0 0.384" xyz="0 0 0"/>
      <geometry>
        <mesh filename="package://cyton_gamma_1500_description/meshes/shoulder_roll.dae"/>
      </geometry>
    </visual>
    <collision>
      <origin rpy="1.5708 0 0" xyz="0 0 0.0587"/>
      <geometry>
        <box size="0.09829 0.18143 0.08392"/>
      </geometry>
    </collision>
    <inertial>
      <mass value="50.0"/>
      <origin rpy="0 0 0" xyz="0 0 0"/>
      <inertia ixx=".1027" ixy="0" ixz="0" iyy=".1027" iyz="0" izz=".1027"/>
    </inertial>
  </link>
  <joint name="joint1" type="revolute">
    <parent link="shoulder_roll"/>
    <child link="shoulder_pitch"/>
    <origin rpy="0 0 0" xyz="0.0205 0 0.12435"/>
    <limit effort="100.0" lower="-1.8326" upper="1.8326" velocity="1.0"/>
    <axis xyz="1 0 0"/>
  </joint>
  <link name="shoulder_pitch">
    <visual>
      <origin rpy="1.5708 0 0" xyz="0 0 0"/>
      <geometry>
        <mesh filename="package://cyton_gamma_1500_description/meshes/shoulder_pitch.dae"/>
      </geometry>
    </visual>
    <collision>
      <origin rpy="1.5708 0 0" xyz="-0.02 -0.001 0.064"/>
      <geometry>
        <box size="0.0709 0.19363 0.083"/>
      </geometry>
    </collision>
    <inertial>
      <mass value="20.0"/>
      <origin rpy="0 0 0" xyz="0 0 0"/>
      <inertia ixx=".0827" ixy="0" ixz="0" iyy=".0827" iyz="0" izz=".0827"/>
    </inertial>
  </link>
  <joint name="joint2" type="revolute">
    <parent link="shoulder_pitch"/>
    <child link="shoulder_yaw"/>
    <origin rpy="0 0 0" xyz="-0.0215 -0.0205 0.1255"/>
    <limit effort="100.0" lower="-1.8326" upper="1.8326" velocity="1.0"/>
    <axis xyz="0 -1 0"/>
  </joint>
  <link name="shoulder_yaw">
    <visual>
      <origin rpy="1.5708 0 -1.5708" xyz="0 0 0.0"/>
      <geometry>
        <mesh filename="package://cyton_gamma_1500_description/meshes/shoulder_yaw.dae"/>
      </geometry>
    </visual>
    <collision>
      <origin rpy="1.5708 0 -1.5708" xyz="-0.003 0.0225 0.057"/>
      <geometry>
        <box size="0.0717 0.1846 0.0756"/>
      </geometry>
    </collision>
    <inertial>
      <mass value="10.0"/>
      <origin rpy="0 0 0" xyz="0 0 0"/>
      <inertia ixx=".0627" ixy="0" ixz="0" iyy=".0627" iyz="0" izz=".0627"/>
    </inertial>
  </link>
  <joint name="joint3" type="revolute">
    <parent link="shoulder_yaw"/>
    <child link="elbow_pitch"/>
    <origin rpy="0 0 0" xyz="0.018 0.0206 0.1158"/>
    <limit effort="100.0" lower="-1.8326" upper="1.8326" velocity="1.0"/>
    <axis xyz="1 0 0"/>
  </joint>
  <link name="elbow_pitch">
    <visual>
      <origin rpy="1.5708 0 3.1416" xyz="0 0 0"/>
      <geometry>
        <mesh filename="package://cyton_gamma_1500_description/meshes/elbow_pitch.dae"/>
      </geometry>
    </visual>
    <collision>
      <origin rpy="1.5708 0 3.1416" xyz="-0.017 0.004 0.0461"/>
      <geometry>
        <box size="0.0549 0.1557 0.076"/>
      </geometry>
    </collision>
    <inertial>
      <mass value="10.0"/>
      <origin rpy="0 0 0" xyz="0 0 0"/>
      <inertia ixx=".0327" ixy="0" ixz="0" iyy=".0327" iyz="0" izz=".0327"/>
    </inertial>
  </link>
  <joint name="joint4" type="revolute">
    <parent link="elbow_pitch"/>
    <child link="elbow_yaw"/>
    <origin rpy="0 0 0" xyz="-0.0171 -0.018 0.09746"/>
    <limit effort="100.0" lower="-1.8326" upper="1.8326" velocity="1.0"/>
    <axis xyz="0 -1 0"/>
  </joint>
  <link name="elbow_yaw">
    <visual>
      <origin rpy="1.5708 0 1.5708" xyz="0 0 0"/>
      <geometry>
        <mesh filename="package://cyton_gamma_1500_description/meshes/elbow_yaw.dae"/>
      </geometry>
    </visual>
    <collision>
      <origin rpy="1.5708 0 1.5708" xyz="0 0.0172 0.047"/>
      <geometry>
        <box size="0.0535 0.1160 0.053"/>
      </geometry>
    </collision>
    <inertial>
      <mass value="10.0"/>
      <origin rpy="0 0 0" xyz="0 0 0"/>
      <inertia ixx=".0227" ixy="0" ixz="0" iyy=".0227" iyz="0" izz=".0227"/>
    </inertial>
  </link>
  <joint name="joint5" type="revolute">
    <parent link="elbow_yaw"/>
    <child link="wrist_pitch"/>
    <origin rpy="0 0 0" xyz="0.02626 0.018 0.0718"/>
    <limit effort="100.0" lower="-1.8326" upper="1.8326" velocity="1.0"/>
    <axis xyz="-1 0 0"/>
  </joint>
  <link name="wrist_pitch">
    <visual>
      <origin rpy="1.5708 0 1.5708" xyz="0 0 0"/>
      <geometry>
        <mesh filename="package://cyton_gamma_1500_description/meshes/wrist_pitch.dae"/>
      </geometry>
    </visual>
    <collision>
      <origin rpy="1.5708 0 1.5708" xyz="-0.013 0 0.05"/>
      <geometry>
        <box size="0.035 0.0435 0.05185"/>
      </geometry>
    </collision>
    <inertial>
      <mass value="10.0"/>
      <origin rpy="0 0 0" xyz="0 0 0"/>
      <inertia ixx=".0127" ixy="0" ixz="0" iyy=".0127" iyz="0" izz=".0127"/>
    </inertial>
  </link>


  <joint name="joint6" type="revolute">
    <parent link="wrist_pitch"/>
    <child link="Wrist"/>
    <origin rpy="0 3.14 0" xyz="-0.026255 0.0 0.115"/>
    <limit effort="100.0" lower="-2.61799" upper="2.61799" velocity="1.0"/>
    <axis xyz="0 0 1"/>
  </joint>




<link name="Wrist">
    <visual>
      <origin rpy="0.0 0 -1.57" xyz=" -0.013 0.015 0.0359"/>
      <geometry>
        <mesh filename="package://urfd_tutorials/urdf/meshes/wrist.dae"/>
      </geometry>
    </visual>
  </link>



  <link name="Motor_+_Base">
    <visual>
      <origin rpy="0.0 0 0" xyz=" 0 -0.045 0"/>
      <geometry>
        <mesh filename="package://urfd_tutorials/urdf/meshes/Motor_+_Base.dae"/>
      </geometry>
    </visual>
  </link>


  <joint name="wrist_to_motor_+_base" type="fixed">
 
    <parent link="Wrist"/>
    <child link="Motor_+_Base"/>
    <origin xyz="0 0.022 0"/>
  </joint>




  <link name="right_link_front">
    <visual>
      <origin rpy="0 -0.6 0" xyz="0 0 0"/>
      <geometry>
        <mesh filename="package://urfd_tutorials/urdf/meshes/right_link_front.dae"/>
      </geometry>
    </visual>
  </link>


  <joint name="joint7" type="revolute">
    <axis xyz="0 1 0"/>
    <limit effort="1000.0" lower="0.0" upper="1.68" velocity="0.5"/>
    <parent link="Motor_+_Base"/>
    <child link="right_link_front"/>
    <origin xyz="0 0 0"/>
  </joint>


  <link name="right_link_back">
    <visual>
      <origin rpy="0.0 0 0" xyz="0 0 0"/>
      <geometry>
        <mesh filename="package://urfd_tutorials/urdf/meshes/right_link_back.dae"/>
      </geometry>
    </visual>
  </link>


  <joint name="motor_base_to_right_link_back" type="revolute">
    <axis xyz="0 1 0"/>
    <limit effort="1000.0" lower="0.0" upper="1.68" velocity="0.5"/>
    <parent link="Motor_+_Base"/>
    <child link="right_link_back"/>
    <origin xyz="0.025 -0.0085 0.015"/>
    <mimic joint="joint7" multiplier="1" offset="0"/> 
  </joint>


  <link name="left_link_front">
    <visual>
      <origin rpy="0 3.142 0" xyz="0 0 0"/>
      <geometry>
        <mesh filename="package://urfd_tutorials/urdf/meshes/left_front_link.dae"/>
      </geometry>
    </visual>
  </link>


  <joint name="motor_base_to_left_link_front" type="revolute">
    <axis xyz="0 1 0"/>
    <limit effort="1000.0" lower="0.0" upper="1.68" velocity="0.5"/>
    <parent link="Motor_+_Base"/>
    <mimic joint="joint7" multiplier="-1" offset="0"/> 
    <child link="left_link_front"/>
    <origin xyz="-0.022 -0.001 0"/>
  </joint>


  <link name="left_link_back">
    <visual>
      <origin rpy="0 3.14 0" xyz="0 0 0"/>
      <geometry>
        <mesh filename="package://urfd_tutorials/urdf/meshes/left_link_back.dae"/>
      </geometry>
    </visual>
  </link>


  <joint name="motor_base_to_left_link_back" type="revolute">
    <axis xyz="0 1 0"/>
    <limit effort="1000.0" lower="0.0" upper="1.68" velocity="0.5"/>
    <parent link="Motor_+_Base"/>
    <child link="left_link_back"/>
    <origin xyz="-0.0469 -0.014 0.0155"/>
    <mimic joint="motor_base_to_left_link_front" multiplier="1" offset="0"/> 
  </joint>



  <link name="one_finger">
    <visual>
      <origin rpy="0 0.003 0" xyz="0 0 0"/>
      <geometry>
        <mesh filename="package://urfd_tutorials/urdf/meshes/one_finger.dae"/>
      </geometry>
    </visual>
  </link>


  <joint name="left_link_back_to_one_finger" type="revolute">
    <axis xyz="0 1 0"/>
    <limit effort="1000.0" lower="0.0" upper="1.68" velocity="0.5"/>
    <parent link="left_link_back"/>
    <child link="one_finger"/>
    <origin xyz="-0.06 0.008 0.0"/>
    <mimic joint="motor_base_to_left_link_front" multiplier="-1" offset="0"/> 
    
  </joint>


  <link name="two_fingers">
    <visual>
      <origin rpy="0 0.24 0" xyz="0 0 0"/>
      <geometry>
        <mesh filename="package://urfd_tutorials/urdf/meshes/two_fingers.dae"/>
      </geometry>
    </visual>
  </link>


  <joint name="right_link_back_to_two_fingers" type="revolute">
    <axis xyz="0 1 0"/>
    <limit effort="1000.0" lower="0.0" upper="1.68" velocity="0.5"/>
    <parent link="right_link_back"/>
    <child link="two_fingers"/>
    <origin xyz="0.06 -0.02 0.0"/>
    <mimic joint="joint7" multiplier="-1" offset="0"/> 
    
  </joint>






</robot>
