<?xml version="1.0"?>
<robot xmlns:xacro="http://wiki.ros.org/xacro" name="cyton_gamma_1500">

  <!-- math definitions -->
  <xacro:property name="M_PI" value="3.141592653589793" />

  <!-- Camera -->
  <xacro:property name="camera_size_link" value="0.008" />

  <!-- gripper joint limits -->
  <xacro:property name="gripper_lower_limit" value="-1.5" />
  <xacro:property name="gripper_upper_limit" value="-0.1" />
  <xacro:property name="gripper_angular_offset" value="1.75" />

  <!-- small mass that can be set to all links -->
  <xacro:property name="small_mass" value="0.0001" />

  <!-- we dont know yet the moment of inertia of the robot! -->
  <xacro:property name="small_inertial_value" value="0.01" />

  <!-- arm macro definition -->
  <xacro:macro name="cyton_gamma_1500" params="prefix">
    <link name="${prefix}base_link">
      <visual>
        <origin xyz="0 0 0" rpy="0 0 0"/>
        <geometry>
          <mesh filename="package://cyton_gamma_1500_description/meshes/arm/base.dae"/>
        </geometry>
      </visual>
      <collision>
        <origin xyz="0 0.0115 0.047"/>
        <geometry>
          <box size="0.154 0.177 0.094"/>
        </geometry>
      </collision>
      <inertial>
        <mass value="${small_mass}" />
        <origin rpy="0 0 0" xyz="0 0 0"/>
        <inertia ixx="1.1027" iyy="1.1027" izz="1.1027"
                 ixy="0" ixz="0" iyz="0"/>
      </inertial>
    </link>

    <joint name="${prefix}joint0" type="revolute">
      <parent link="${prefix}base_link" />
      <child link="${prefix}shoulder_roll" />
      <origin xyz="0 0 0.05315" rpy="0 0 0" />
      <limit lower="-2.5509" upper="2.5585" effort="100.0" velocity="1.0" />
      <axis xyz="0 0 1" />
    </joint>

    <link name="${prefix}shoulder_roll">
      <visual>
        <origin xyz="0 0 0" rpy="0 0 0.384"/>
        <geometry>
          <mesh filename="package://cyton_gamma_1500_description/meshes/arm/shoulder_roll.dae"/>
        </geometry>
      </visual>
      <collision>
        <origin xyz="0 0 0.0587" rpy="1.5708 0 0"/>
        <geometry>
          <box size="0.09829 0.18143 0.08392"/>
        </geometry>
      </collision>
      <inertial>
        <mass value="${small_mass}" />
        <origin rpy="0 0 0" xyz="0 0 0"/>
        <inertia ixx=".1027" iyy=".1027" izz=".1027"
                 ixy="0" ixz="0" iyz="0"/>
      </inertial>
    </link>

    <joint name="${prefix}joint1" type="revolute">
      <parent link="${prefix}shoulder_roll" />
      <child link="${prefix}shoulder_pitch" />
      <origin xyz="0.0205 0 0.12435" rpy="0 0 0" />
      <limit lower="-1.707" upper="1.6379" effort="100.0" velocity="1.0" />
      <axis xyz="1 0 0" />
    </joint>

    <link name="${prefix}shoulder_pitch">
      <visual>
        <origin xyz="0 0 0" rpy="0 0 0" />
        <geometry>
          <mesh filename="package://cyton_gamma_1500_description/meshes/arm/shoulder_pitch.dae"/>
        </geometry>
      </visual>
      <collision>
        <origin xyz="-0.02 -0.001 0.064" rpy="1.5708 0 0"/>
        <geometry>
          <box size="0.0709 0.19363 0.083"/>
        </geometry>
      </collision>
      <inertial>
        <mass value="${small_mass}" />
        <origin rpy="0 0 0" xyz="0 0 0"/>
        <inertia ixx=".0827" iyy=".0827" izz=".0827"
                 ixy="0" ixz="0" iyz="0"/>
      </inertial>
    </link>

    <joint name="${prefix}joint2" type="revolute">
      <parent link="${prefix}shoulder_pitch" />
      <child link="${prefix}shoulder_yaw" />
      <origin xyz="-0.0215 -0.0205 0.1255" rpy="0 0 0" />
      <limit lower="-1.5459" upper="1.73" effort="100.0" velocity="1.0" />
      <axis xyz="0 -1 0" />
    </joint>

    <link name="${prefix}shoulder_yaw">
      <visual>
        <origin xyz="0 0 0.0" rpy="0 0 -1.5708" />
        <geometry>
          <mesh filename="package://cyton_gamma_1500_description/meshes/arm/shoulder_yaw.dae"/>
        </geometry>
      </visual>
      <collision>
        <origin xyz="-0.003 0.0225 0.057" rpy="1.5708 0 -1.5708"/>
        <geometry>
          <box size="0.0717 0.1846 0.0756"/>
        </geometry>
      </collision>
      <inertial>
        <mass value="${small_mass}" />
        <origin rpy="0 0 0" xyz="0 0 0"/>
        <inertia ixx=".0627" iyy=".0627" izz=".0627"
                 ixy="0" ixz="0" iyz="0"/>
      </inertial>
    </link>

    <joint name="${prefix}joint3" type="revolute">
      <parent link="${prefix}shoulder_yaw" />
      <child link="${prefix}elbow_pitch" />
      <origin xyz="0.018 0.0206 0.1158" rpy="0 0 0" />
      <limit lower="-1.6072" upper="1.6149" effort="100.0" velocity="1.0" />
      <axis xyz="1 0 0" />
    </joint>

    <link name="${prefix}elbow_pitch">
      <visual>
        <origin xyz="0 0 0" rpy="1.5708 0 3.1416" />
        <geometry>
          <mesh filename="package://cyton_gamma_1500_description/meshes/arm/elbow_pitch.dae"/>
        </geometry>
      </visual>
      <collision>
        <origin xyz="-0.017 0.004 0.0461" rpy="1.5708 0 3.1416"/>
        <geometry>
          <box size="0.0549 0.1557 0.076"/>
        </geometry>
      </collision>
      <inertial>
        <mass value="${small_mass}" />
        <origin rpy="0 0 0" xyz="0 0 0"/>
        <inertia ixx=".0327" iyy=".0327" izz=".0327"
                 ixy="0" ixz="0" iyz="0"/>
      </inertial>
    </link>

    <joint name="${prefix}joint4" type="revolute">
      <parent link="${prefix}elbow_pitch" />
      <child link="${prefix}elbow_yaw" />
      <origin xyz="-0.0171 -0.018 0.09746" rpy="0 0 0" />
      <limit lower="-1.8757" upper="1.4615" effort="100.0" velocity="1.0" />
      <axis xyz="0 -1 0" />
    </joint>

    <link name="${prefix}elbow_yaw">
      <visual>
        <origin xyz="0 0 0" rpy="0 0 1.5708" />
        <geometry>
          <mesh filename="package://cyton_gamma_1500_description/meshes/arm/elbow_yaw.dae"/>
        </geometry>
      </visual>
      <collision>
        <origin xyz="0 0.0172 0.047" rpy="1.5708 0 1.5708" />
        <geometry>
          <box size="0.0535 0.1160 0.053"/>
        </geometry>
      </collision>
      <inertial>
        <mass value="${small_mass}" />
        <origin rpy="0 0 0" xyz="0 0 0"/>
        <inertia ixx=".0227" iyy=".0227" izz=".0227"
                 ixy="0" ixz="0" iyz="0"/>
      </inertial>
    </link>

    <joint name="${prefix}joint5" type="revolute">
      <parent link="${prefix}elbow_yaw" />
      <child link="${prefix}wrist_pitch" />
      <origin xyz="-0.02626 0.018 0.0718" rpy="0 0 ${M_PI}" />
      <limit lower="-1.5766" upper="1.5382" effort="100.0" velocity="1.0" />
      <axis xyz="-1 0 0" />
    </joint>

    <link name="${prefix}wrist_pitch">
      <visual>
        <origin xyz="0 0 0" rpy="1.5708 0 1.5708" />
        <geometry>
          <mesh filename="package://cyton_gamma_1500_description/meshes/arm/wrist_pitch.dae"/>
        </geometry>
      </visual>
      <!--inertial>
        <mass value="${small_mass}" />
        <origin rpy="0 0 0" xyz="0 0 0"/>
        <inertia ixx=".0127" iyy=".0127" izz=".0127"
                  ixy="0" ixz="0" iyz="0"/>
      </inertial-->
      <inertial>
        <mass value="${small_mass}"/>
        <origin rpy="0 0 0" xyz="0 0 0"/>
        <inertia ixx="${small_inertial_value}" ixy="0" ixz="0"
                iyy="${small_inertial_value}" iyz="0" izz="${small_inertial_value}"/>
      </inertial>
    </link>

    <joint name="${prefix}joint6" type="revolute">
      <parent link="${prefix}wrist_pitch" />
      <child link="${prefix}Wrist" />
      <origin rpy="0 3.14 0" xyz="-0.026255 0.0 0.115"/>
      <limit lower="-2.5279" upper="2.5355" effort="100.0" velocity="1.0" />
      <axis xyz="0 0 -1" />
    </joint>

    <link name="${prefix}Wrist">
      <visual>
        <origin rpy="0.0 0 -1.57" xyz=" -0.013 0.015 0.0359"/>
        <geometry>
          <mesh filename="package://cyton_gamma_1500_description/meshes/arm/wrist.dae"/>
        </geometry>
      </visual>
      <!--collision>
        <origin rpy="0.0 0 -1.57" xyz=" -0.013 0.015 0.0359"/>
        <geometry>
          <box size="0.0001 0.0001 0.0001"/>
        </geometry>
      </collision-->
      <collision>
        <origin rpy="0.0 0 -1.57" xyz="-0.013 0 0.0359"/>
        <geometry>
          <box size="0.06 0.09 0.1"/>
        </geometry>
      </collision>
      <inertial>
        <mass value="${small_mass}"/>
        <origin rpy="0 0 0" xyz="0 0 0"/>
        <inertia ixx="${small_inertial_value}" ixy="0" ixz="0"
                iyy="${small_inertial_value}" iyz="0" izz="${small_inertial_value}"/>
      </inertial>
    </link>

    <link name="${prefix}Motor_+_Base">
      <visual>
        <origin rpy="0.0 0 0" xyz=" 0 -0.045 0"/>
        <geometry>
          <mesh filename="package://cyton_gamma_1500_description/meshes/gripper/Motor_+_Base.dae"/>
        </geometry>
      </visual>
      <inertial>
        <mass value="${small_mass}"/>
        <origin rpy="0 0 0" xyz="0 0 0"/>
        <inertia ixx="${small_inertial_value}" ixy="0" ixz="0"
                iyy="${small_inertial_value}" iyz="0" izz="${small_inertial_value}"/>
      </inertial>
    </link>

    <joint name="${prefix}wrist_to_motor_+_base" type="fixed">
      <parent link="${prefix}Wrist" />
      <child link="${prefix}Motor_+_Base" />
      <origin xyz="0 0.022 0"/>
    </joint>

    <link name="${prefix}right_link_front">
      <visual>
        <origin rpy="0 -0.6 0" xyz="0 0 0"/>
        <geometry>
          <mesh filename="package://cyton_gamma_1500_description/meshes/gripper/right_link_front.dae"/>
        </geometry>
      </visual>
      <inertial>
        <mass value="${small_mass}"/>
        <origin rpy="0 0 0" xyz="0 0 0"/>
        <inertia ixx="${small_inertial_value}" ixy="0" ixz="0"
                iyy="${small_inertial_value}" iyz="0" izz="${small_inertial_value}"/>
      </inertial>
    </link>

    <joint name="${prefix}gripper_joint" type="revolute">
      <parent link="${prefix}Motor_+_Base" />
      <child link="${prefix}right_link_front" />
      <origin xyz="0 0 0" rpy="0 ${gripper_angular_offset} 0" />
      <limit effort="1000.0" lower="${gripper_lower_limit}" upper="${gripper_upper_limit}" velocity="0.5"/>
      <axis xyz="0 1 0" />
    </joint>

    <link name="${prefix}right_link_back">
      <visual>
        <origin rpy="0.0 0 0" xyz="0 0 0"/>
        <geometry>
          <mesh filename="package://cyton_gamma_1500_description/meshes/gripper/right_link_back.dae"/>
        </geometry>
      </visual>
      <inertial>
        <mass value="${small_mass}"/>
        <origin rpy="0 0 0" xyz="0 0 0"/>
        <inertia ixx="${small_inertial_value}" ixy="0" ixz="0"
                iyy="${small_inertial_value}" iyz="0" izz="${small_inertial_value}"/>
      </inertial>
    </link>

    <joint name="${prefix}motor_base_to_right_link_back" type="revolute">
      <parent link="${prefix}Motor_+_Base" />
      <child link="${prefix}right_link_back" />
      <origin xyz="0.025 -0.0085 0.015" rpy="0 ${gripper_angular_offset} 0" />
      <axis xyz="0 1 0" />
      <limit effort="1000.0" lower="${gripper_lower_limit}" upper="${gripper_upper_limit}" velocity="0.5"/>
      <mimic joint="${prefix}gripper_joint" multiplier="1" offset="0"/>
    </joint>

    <link name="${prefix}left_link_front">
      <visual>
        <origin rpy="0 3.142 0" xyz="0 0 0"/>
        <geometry>
          <mesh filename="package://cyton_gamma_1500_description/meshes/gripper/left_front_link.dae"/>
        </geometry>
      </visual>
      <inertial>
        <mass value="${small_mass}"/>
        <origin rpy="0 0 0" xyz="0 0 0"/>
        <inertia ixx="${small_inertial_value}" ixy="0" ixz="0"
                iyy="${small_inertial_value}" iyz="0" izz="${small_inertial_value}"/>
      </inertial>
    </link>

    <joint name="${prefix}motor_base_to_left_link_front" type="revolute">
      <parent link="${prefix}Motor_+_Base" />
      <child link="${prefix}left_link_front" />
      <origin xyz="-0.022 -0.001 0" rpy="0 -${gripper_angular_offset} 0" />
      <axis xyz="0 1 0" />
      <limit effort="1000.0" lower="${-gripper_upper_limit}" upper="${-gripper_lower_limit}" velocity="0.5"/>
      <mimic joint="${prefix}gripper_joint" multiplier="-1" offset="0"/>
    </joint>

    <link name="${prefix}left_link_back">
      <visual>
        <origin rpy="0 3.14 0" xyz="0 0 0"/>
        <geometry>
          <mesh filename="package://cyton_gamma_1500_description/meshes/gripper/left_link_back.dae"/>
        </geometry>
      </visual>
      <inertial>
        <mass value="${small_mass}"/>
        <origin rpy="0 0 0" xyz="0 0 0"/>
        <inertia ixx="${small_inertial_value}" ixy="0" ixz="0"
                iyy="${small_inertial_value}" iyz="0" izz="${small_inertial_value}"/>
      </inertial>
    </link>

    <joint name="${prefix}motor_base_to_left_link_back" type="revolute">
      <parent link="${prefix}Motor_+_Base" />
      <child link="${prefix}left_link_back" />
      <origin xyz="-0.0469 -0.014 0.0155" rpy="0 -${gripper_angular_offset} 0" />
      <axis xyz="0 1 0" />
      <limit effort="1000.0" lower="${-gripper_upper_limit}" upper="${-gripper_lower_limit}" velocity="0.5"/>
      <mimic joint="${prefix}gripper_joint" multiplier="-1" offset="0"/>
    </joint>

    <link name="${prefix}one_finger">
      <visual>
        <origin rpy="0 0.003 0" xyz="0 0 0"/>
        <geometry>
          <mesh filename="package://cyton_gamma_1500_description/meshes/gripper/one_finger.dae"/>
        </geometry>
      </visual>
      <collision>
        <origin rpy="0 -0.05 0" xyz="0.014 -0.001 -0.07"/>
        <geometry>
          <box size="0.045 0.025 0.169"/>
        </geometry>
      </collision>
      <inertial>
        <mass value="${small_mass}"/>
        <origin rpy="0 0 0" xyz="0 0 0"/>
        <inertia ixx="${small_inertial_value}" ixy="0" ixz="0"
                iyy="${small_inertial_value}" iyz="0" izz="${small_inertial_value}"/>
      </inertial>
    </link>

    <joint name="${prefix}left_link_back_to_one_finger" type="revolute">
      <parent link="${prefix}left_link_back" />
      <child link="${prefix}one_finger" />
      <origin xyz="-0.06 0.008 0.0" rpy="0 ${gripper_angular_offset} 0" />
      <axis xyz="0 1 0" />
      <limit effort="1000.0" lower="${gripper_lower_limit}" upper="${gripper_upper_limit}" velocity="0.5"/>
      <mimic joint="${prefix}gripper_joint" multiplier="1" offset="0"/>
    </joint>

    <link name="${prefix}two_fingers">
      <visual>
        <origin rpy="0 0.24 0" xyz="0 0 0"/>
        <geometry>
          <mesh filename="package://cyton_gamma_1500_description/meshes/gripper/two_fingers.dae"/>
        </geometry>
      </visual>
      <collision>
        <origin rpy="0 0.1 0" xyz="-0.02 0.024 -0.07"/>
        <geometry>
          <box size="0.045 0.07 0.165"/>
        </geometry>
      </collision>
      <inertial>
        <mass value="${small_mass}"/>
        <origin rpy="0 0 0" xyz="0 0 0"/>
        <inertia ixx="${small_inertial_value}" ixy="0" ixz="0"
                iyy="${small_inertial_value}" iyz="0" izz="${small_inertial_value}"/>
      </inertial>
    </link>

    <gazebo reference="${prefix}one_finger">
      <mu1 value="50.0"/>
      <mu2 value="50.0"/> <!-- enable gripper finger friction-->
      <material>Gazebo/DepthMapVS</material>
    </gazebo>

    <gazebo reference="${prefix}two_fingers">
      <mu1 value="50.0"/>
      <mu2 value="50.0"/> <!-- enable gripper fingers friction-->
      <material>Gazebo/DepthMapVS</material>
    </gazebo>

    <joint name="${prefix}right_link_back_to_two_fingers" type="revolute">
      <parent link="${prefix}right_link_back" />
      <child link="${prefix}two_fingers" />
      <origin xyz="0.06 -0.02 0.0" rpy="0 -${gripper_angular_offset} 0" />
      <axis xyz="0 1 0" />
      <limit effort="1000.0" lower="${-gripper_upper_limit}" upper="${-gripper_lower_limit}" velocity="0.5"/>
      <mimic joint="${prefix}gripper_joint" multiplier="-1" offset="0"/>
    </joint>

    <joint name="${prefix}virtual_endeffector_joint" type="fixed">
      <parent link="${prefix}Wrist" />
      <child link="${prefix}virtual_endeffector" />
      <origin xyz="-0.012 0.018 -0.130" rpy="0 0 0" /> <!-- set this value also in mbot pregrasp planning gripper matrix -->
    </joint>

    <link name="${prefix}virtual_endeffector">
      <visual>
        <origin xyz="0 0 0" rpy="0 0 0" />
        <geometry>
          <sphere radius="0.002" />
        </geometry>
        <material name="grey">
          <color rgba="0.7 0.7 0.7 0.8" />
        </material>
      </visual>
    </link>

    <!-- Camera -->
    <!-- Camera: Colour : Base_Camera_link -->
    <gazebo reference="${prefix}base_camera_link">
      <material>Gazebo/FlatBlack</material>
    </gazebo>

    <!-- Camera: Colour : Camera_link -->
    <gazebo reference="${prefix}camera_link">
      <material>Gazebo/RedTransparent</material>
    </gazebo>

    <!-- Camera: Joint : Wrist to Base_Camera -->
    <joint name="${prefix}joint_base_camera" type="fixed">
      <origin xyz="0 0 0.02" rpy="0 0 0"/>
      <parent link="${prefix}Wrist" />
      <child link="${prefix}base_camera_link" />
    </joint>

    <!-- Camera: Base Camera Link -->
    <link name="${prefix}base_camera_link">
      <collision>
        <origin xyz="0 0.03 0" rpy="0 0 0"/>
        <geometry>
          <box size="0.01 0.05 0.01"/>
        </geometry>
      </collision>
      <visual>
        <origin xyz="0 0.03 0" rpy="0 0 0"/>
        <geometry>
          <box size="0.01 0.05 0.01"/>
        </geometry>
      </visual>
      <inertial>
        <mass value="0.01" />
        <origin xyz="0 0.03 0" rpy="0 0 0"/>
        <inertia ixx="1.666666e-07" ixy="0.0" ixz="0.0" iyy="1.666666e-07" iyz="0.0" izz="1.666666e-07"/>
      </inertial>
    </link>

    <!-- Camera: Joint : Base_Camera to Camera -->
    <joint name="{prefix}camera_link" type="fixed">
      <origin xyz="0 0.05 -0.005" rpy="-1.7 1.7 0"/>
      <parent link="${prefix}base_camera_link"/>
      <child link="${prefix}camera_link"/>
    </joint>

    <!-- Camera -->
    <link name="${prefix}camera_link">
      <collision>
        <origin xyz="0 0 0" rpy="0 0 0"/>
        <geometry>
          <box size="${camera_size_link} ${camera_size_link} ${camera_size_link}"/>
        </geometry>
      </collision>
      <visual>
        <origin xyz="0 0 0" rpy="0 0 0"/>
        <geometry>
          <box size="${camera_size_link} ${camera_size_link} ${camera_size_link}"/>
        </geometry>
      </visual>
      <inertial>
        <mass value="1e-5" />
        <origin xyz="0 0 0" rpy="0 0 0"/>
        <inertia ixx="1e-6" ixy="0" ixz="0" iyy="1e-6" iyz="0" izz="1e-6" />
      </inertial>
    </link>

    <!-- Camera: plugin -->
    <gazebo reference="${prefix}camera_link">
      <sensor type="camera" name="camera_grasping">
        <update_rate>30.0</update_rate>
        <camera name="head">
          <horizontal_fov>1.3962634</horizontal_fov>
          <image>
            <width>800</width>
            <height>800</height>
            <format>R8G8B8</format>
          </image>
          <clip>
            <near>0.02</near>
            <far>300</far>
          </clip>
          <noise>
            <type>gaussian</type>
            <mean>0.0</mean>
            <stddev>0.007</stddev>
          </noise>
        </camera>
        <plugin name="camera_controller" filename="libgazebo_ros_camera.so">
          <alwaysOn>true</alwaysOn>
          <updateRate>0.0</updateRate>
          <cameraName>gripper_camera</cameraName>
          <imageTopicName>image_raw</imageTopicName>
          <cameraInfoTopicName>camera_info</cameraInfoTopicName>
          <frameName>camera_link</frameName>
          <hackBaseline>0.07</hackBaseline>
          <distortionK1>0.0</distortionK1>
          <distortionK2>0.0</distortionK2>
          <distortionK3>0.0</distortionK3>
          <distortionT1>0.0</distortionT1>
          <distortionT2>0.0</distortionT2>
        </plugin>
      </sensor>
    </gazebo>

   <!-- to attach objects when grasping -->
    <gazebo>
      <plugin name="gazebo_grasp_fix" filename="libgazebo_grasp_fix.so">
        <arm>
        <arm_name>${prefix}</arm_name>
          <palm_link>${prefix}Wrist</palm_link>
          <gripper_link>${prefix}one_finger</gripper_link>
          <gripper_link>${prefix}two_fingers</gripper_link>
        </arm>
        <forces_angle_tolerance>100</forces_angle_tolerance>
        <update_rate>4</update_rate>
        <grip_count_threshold>4</grip_count_threshold>
        <max_grip_count>8</max_grip_count>
        <release_tolerance>0.005</release_tolerance>
        <disable_collisions_on_attach>false</disable_collisions_on_attach>
        <contact_topic>__default_topic__</contact_topic>
      </plugin>
    </gazebo>
  </xacro:macro> <!-- end of mbot arm macro -->

  <!-- plugin to support mimic joints in gazebo -->
  <xacro:macro name="mimic_joints_macro" params="joint_to_be_mimiced mimic_joint multiplier">
    <gazebo>
      <plugin name="${mimic_joint}_mimic_plugin" filename="libroboticsgroup_gazebo_mimic_joint_plugin.so" >
        <joint>left_arm_${joint_to_be_mimiced}</joint>
        <mimicJoint>left_arm_${mimic_joint}</mimicJoint>
        <multiplier>${multiplier}</multiplier>
        <offset>0.0</offset>
      </plugin>
    </gazebo>
  </xacro:macro>

  <!-- plugin to support mimic joints in gazebo -->
  <xacro:macro name="mimic_joints_macro" params="joint_to_be_mimiced mimic_joint multiplier">
    <gazebo>
      <plugin name="${mimic_joint}_mimic_plugin" filename="libroboticsgroup_gazebo_mimic_joint_plugin.so" >
          <joint>left_arm_${joint_to_be_mimiced}</joint>
          <mimicJoint>left_arm_${mimic_joint}</mimicJoint>
          <multiplier>${multiplier}</multiplier>
          <offset>0.0</offset>
      </plugin>
    </gazebo>
  </xacro:macro>

  <!-- left side of gripper -->
  <xacro:mimic_joints_macro joint_to_be_mimiced="gripper_joint" mimic_joint="motor_base_to_left_link_front" multiplier="-1.0" />
  <xacro:mimic_joints_macro joint_to_be_mimiced="gripper_joint" mimic_joint="motor_base_to_left_link_back" multiplier="-1.0" />
  <xacro:mimic_joints_macro joint_to_be_mimiced="gripper_joint" mimic_joint="left_link_back_to_one_finger" multiplier="1.0" />

  <!-- right side of gripper -->
  <!-- right_link_front is actuated by gripper joint, therefore no need for mimic plugin -->
  <xacro:mimic_joints_macro joint_to_be_mimiced="gripper_joint" mimic_joint="motor_base_to_right_link_back" multiplier="1.0" />
  <xacro:mimic_joints_macro joint_to_be_mimiced="gripper_joint" mimic_joint="right_link_back_to_two_fingers" multiplier="-1.0" />

  <!--<gazebo> ROS control publishes joint states currently, so no need for gazebo to do it
    <plugin name="joint_state_publisher"
            filename="libgazebo_ros_joint_state_publisher.so">
      <jointName>left_arm_joint0, left_arm_joint1, left_arm_joint2, left_arm_joint3, left_arm_joint4, left_arm_joint5,
            left_arm_joint6, left_arm_gripper_joint</jointName>
      <robotNamespace>/</robotNamespace>
      <updateRate>50.0</updateRate>
    </plugin>
  </gazebo>-->

  <!-- arm transmission macro (needed to actuate joints in gazebo simulator via ROS control) -->
  <xacro:macro name="arm_transmission_macro" params="joint_name">
    <transmission name="${joint_name}_arm_trans">
      <type>transmission_interface/SimpleTransmission</type>
      <joint name="${joint_name}">
        <hardwareInterface>hardware_interface/VelocityJointInterface</hardwareInterface>
      </joint>
      <actuator name="${joint_name}_actuator">
        <mechanicalReduction>1</mechanicalReduction>
      </actuator>
    </transmission>
  </xacro:macro>

  <!-- joint0 -->
  <xacro:arm_transmission_macro joint_name="left_arm_joint0" />

  <!-- joint1 -->
  <xacro:arm_transmission_macro joint_name="left_arm_joint1" />

  <!-- joint2 -->
  <xacro:arm_transmission_macro joint_name="left_arm_joint2" />

  <!-- joint3 -->
  <xacro:arm_transmission_macro joint_name="left_arm_joint3" />

  <!-- joint4 -->
  <xacro:arm_transmission_macro joint_name="left_arm_joint4" />

  <!-- joint5 -->
  <xacro:arm_transmission_macro joint_name="left_arm_joint5" />

  <!-- joint6 -->
  <xacro:arm_transmission_macro joint_name="left_arm_joint6" />

  <!-- gripper joint 1 -->
  <xacro:arm_transmission_macro joint_name="left_arm_gripper_joint" />

</robot>
